Workbook

Sheet Inputs
A1: fu
A2: Rose cells are inputs. Gray cells marked CONFIRM are placeholders to replace. White cells are formulas. Gimbal at origin, y up, mm.
A3: Parameter | B3: Value | C3: Unit | D3: Note / source | R3: Chart data (auto) for the layout plot
A4: Mount locations | R4: Chamber outline | T4: Chamber outline (mirror) | V4: Chamber axis | X4: Actuator, neutral | Z4: Actuator at +max angle | AB4: Actuator at −max angle | AD4: 6 in limit | AF4: 6 in limit (mirror) | AH4: Gimbal
A5: Actuator rear pin, radial (A x) | B5: 250 | C5: mm | D5: max dia 300 / 2 | R5: x | S5: y | T5: x | U5: y | V5: x | W5: y | X5: x | Y5: y | Z5: x | AA5: y | AB5: x | AC5: y | AD5: x | AE5: y | AF5: x | AG5: y | AH5: x | AI5: y
A6: Actuator rear pin, axial (A y) | B6: 100 | C6: mm | D6: Above the gimbal is + | R6: =Inputs!$C$68 -> 88.9 | S6: =-Inputs!$B$68 -> -60 | T6: =-Inputs!$C$68 -> -88.9 | U6: =-Inputs!$B$68 -> -60 | V6: =0 -> 0 | W6: =0 -> 0 | X6: =Inputs!$B$5 -> 250 | Y6: =Inputs!$B$6 -> 100 | Z6: =Inputs!$B$5 -> 250 | AA6: =Inputs!$B$6 -> 100 | AB6: =Inputs!$B$5 -> 250 | AC6: =Inputs!$B$6 -> 100 | AD6: =Inputs!$B$38 -> 350 | AE6: =350 -> 350 | AF6: =-Inputs!$B$38 -> -350 | AG6: =350 -> 350 | AH6: =0 -> 0 | AI6: =0 -> 0
A7: Chamber pin, axial (P y) | B7: -200 | C7: mm | D7: Allowed pad stations: −260.7 to −74.0 | R7: =IF(Inputs!$C$69=0,R6,Inputs!$C$69) -> 64.855 | S7: =IF(Inputs!$C$69=0,S6,-Inputs!$B$69) -> -95 | T7: =IF(Inputs!$C$69=0,T6,-Inputs!$C$69) -> -64.855 | U7: =IF(Inputs!$C$69=0,U6,-Inputs!$B$69) -> -95 | V7: =0 -> 0 | W7: =-Inputs!$B$21 -> -378.678 | X7: =Inputs!$B$11 -> 95.855 | Y7: =Inputs!$B$7 -> -200 | Z7: =Geometry!D6 -> 129.12838 | AA7: =Geometry!D7 -> -180.3165 | AB7: =Geometry!B6 -> 59.669112 | AC7: =Geometry!B7 -> -213.6066 | AD7: =Inputs!$B$38 -> 350 | AE7: =-420 -> -420 | AF7: =-Inputs!$B$38 -> -350 | AG7: =-420 -> -420
A8: Chamber outer radius at pad station | B8: 64.855 | C8: mm | R8: =IF(Inputs!$C$70=0,R7,Inputs!$C$70) -> 35.43 | S8: =IF(Inputs!$C$70=0,S7,-Inputs!$B$70) -> -299.718 | T8: =IF(Inputs!$C$70=0,T7,-Inputs!$C$70) -> -35.43 | U8: =IF(Inputs!$C$70=0,U7,-Inputs!$B$70) -> -299.718
A9: Pad thickness | B9: 1 | C9: mm | D9: Per clevis drawing | R9: =IF(Inputs!$C$71=0,R8,Inputs!$C$71) -> 79 | S9: =IF(Inputs!$C$71=0,S8,-Inputs!$B$71) -> -398.678 | T9: =IF(Inputs!$C$71=0,T8,-Inputs!$C$71) -> -79 | U9: =IF(Inputs!$C$71=0,U8,-Inputs!$B$71) -> -398.678
A10: Pin height above pad | B10: 30 | C10: mm | D10: Rod eye head clearance; per clevis drawing | R10: =IF(Inputs!$C$72=0,R9,Inputs!$C$72) -> 79 | S10: =IF(Inputs!$C$72=0,S9,-Inputs!$B$72) -> -398.678 | T10: =IF(Inputs!$C$72=0,T9,-Inputs!$C$72) -> -79 | U10: =IF(Inputs!$C$72=0,U9,-Inputs!$B$72) -> -398.678
A11: Chamber pin, radial (P x) | B11: =B8+B9+B10 -> 95.855 | C11: mm | D11: Formula: chamber radius + pad + pin height
A12: Motion requirements | B12: 4
A13: Required gimbal angle (per axis, ±) | B13: 10 | C13: deg
A14: Max gimbal rate | B14: 20 | C14: deg/s
A15: Max gimbal angular accel | B15: 30 | C15: deg/s^2
A16: Engine and vehicle
A17: Thrust | B17: 2000 | C17: lbf
A18: Engine-side (gimbaled) mass | B18: 20 | C18: lb
A19: CG distance below gimbal | B19: 162.422 | C19: mm
A20: Gimbal to throat | B20: 279.718 | C20: mm
A21: Gimbal to nozzle exit | B21: 378.678 | C21: mm
A22: Max vehicle acceleration | B22: 5 | C22: g | D22: CONFIRM: 1 for test stand; flight = T / burnout mass
A23: Load assumptions
A24: Gimbal bearing radius | B24: 12.7 | C24: mm | D24: CONFIRM:
A25: Gimbal bearing friction coefficient | B25: 0.15 | C25: - | D25: CONFIRM: PTFE-lined ~0.05–0.1, greased steel ~0.1–0.2
A26: Thrust misalignment, offset | B26: 1.5 | C26: mm | D26: CONFIRM:
A27: Thrust misalignment, angle | B27: 0.5 | C27: deg | D27: CONFIRM:
A28: Startup side load fraction | B28: 0.1 | C28: of T | D28: CONFIRM: Applied at nozzle exit
A29: Hose torque at max angle | B29: 50 | C29: N*m | D29: CONFIRM: Needs line specs or a bend test
A30: Load uncertainty margin | B30: 1.5 | C30: -
A31: Actuator
A32: Actuator (exact name from Actuators tab) | B32: IMA33-RN04 (1-stack)
A33: Stroke to order (0 = auto-center neutral) | B33: 0 | C33: mm | D33: Enter the catalog stroke once chosen
A34: Overtravel margin at each end of stroke | B34: 5 | C34: mm | D34: Keeps the actuator off its internal stops
A35: Pin-to-pin length adder over catalog length | B35: 0 | C35: mm | D35: CONFIRM: Rod eye / rear clevis length if catalog lengths aren't pin-to-pin — check drawing
A36: Exposed rod + rod eye when fully retracted | B36: 40 | C36: mm | D36: CONFIRM: Body length ≈ retracted pin-to-pin − this — check drawing
A37: Envelope and clearance
A38: Max radius from vehicle centerline | B38: 350 | C38: mm | D38: Nothing may pass this at any gimbal angle
A39: Min clearance, actuator to chamber | B39: 3 | C39: mm
A40: Zone near chamber pin ignored for clearance | B40: 25 | C40: mm | D40: Rod eye / clevis region, contact there is by design
...

Sheet Geometry
A1: Actuator kinematics vs gimbal angle
A3: Quantity | B3: Min angle | C3: Neutral | D3: Max angle | E3: Unit | T3: Chart data (auto)
A4: Gimbal angle θ | B4: =-Inputs!$B$13 -> -10 | C4: =0 -> 0 | D4: =Inputs!$B$13 -> 10 | E4: deg | T4: Angle (deg) | U4: Pin-to-pin L | V4: Usable min | W4: Usable max | X4: Moment arm
A5: θ | B5: =RADIANS(B4) -> -0.17453293 | C5: =RADIANS(C4) -> 0 | D5: =RADIANS(D4) -> 0.17453293 | E5: rad | T5: -15 | U5: =SQRT(((Inputs!$B$11*COS(RADIANS(T5))-Inputs!$B$7*SIN(RADIANS(T5)))-Inputs!$B$5)^2+((Inputs!$B$11*SIN(RADIANS(T5))+Inputs!$B$7*COS(RADIANS(T5)))-Inputs!$B$6)^2) -> 380.62387 | V5: =Validation!$B$14 -> 302.08952 | W5: =Validation!$B$15 -> 372.47903 | X5: =ABS(Inputs!$B$5*(Inputs!$B$11*SIN(RADIANS(T5))+Inputs!$B$7*COS(RADIANS(T5)))-Inputs!$B$6*(Inputs!$B$11*COS(RADIANS(T5))-Inputs!$B$7*SIN(RADIANS(T5))))/U5 -> 153.90802
A6: Chamber pin x (rotated) | B6: =Inputs!$B$11*COS(B5)-Inputs!$B$7*SIN(B5) -> 59.669112 | C6: =Inputs!$B$11*COS(C5)-Inputs!$B$7*SIN(C5) -> 95.855 | D6: =Inputs!$B$11*COS(D5)-Inputs!$B$7*SIN(D5) -> 129.12838 | E6: mm | T6: -14 | U6: =SQRT(((Inputs!$B$11*COS(RADIANS(T6))-Inputs!$B$7*SIN(RADIANS(T6)))-Inputs!$B$5)^2+((Inputs!$B$11*SIN(RADIANS(T6))+Inputs!$B$7*COS(RADIANS(T6)))-Inputs!$B$6)^2) -> 377.92358 | V6: =Validation!$B$14 -> 302.08952 | W6: =Validation!$B$15 -> 372.47903 | X6: =ABS(Inputs!$B$5*(Inputs!$B$11*SIN(RADIANS(T6))+Inputs!$B$7*COS(RADIANS(T6)))-Inputs!$B$6*(Inputs!$B$11*COS(RADIANS(T6))-Inputs!$B$7*SIN(RADIANS(T6))))/U6 -> 155.51947
A7: Chamber pin y (rotated) | B7: =Inputs!$B$11*SIN(B5)+Inputs!$B$7*COS(B5) -> -213.6066 | C7: =Inputs!$B$11*SIN(C5)+Inputs!$B$7*COS(C5) -> -200 | D7: =Inputs!$B$11*SIN(D5)+Inputs!$B$7*COS(D5) -> -180.3165 | E7: mm | T7: -13 | U7: =SQRT(((Inputs!$B$11*COS(RADIANS(T7))-Inputs!$B$7*SIN(RADIANS(T7)))-Inputs!$B$5)^2+((Inputs!$B$11*SIN(RADIANS(T7))+Inputs!$B$7*COS(RADIANS(T7)))-Inputs!$B$6)^2) -> 375.19529 | V7: =Validation!$B$14 -> 302.08952 | W7: =Validation!$B$15 -> 372.47903 | X7: =ABS(Inputs!$B$5*(Inputs!$B$11*SIN(RADIANS(T7))+Inputs!$B$7*COS(RADIANS(T7)))-Inputs!$B$6*(Inputs!$B$11*COS(RADIANS(T7))-Inputs!$B$7*SIN(RADIANS(T7))))/U7 -> 157.11812
A8: Actuator length L (pin to pin) | B8: =SQRT((B6-Inputs!$B$5)^2+(B7-Inputs!$B$6)^2) -> 366.84458 | C8: =SQRT((C6-Inputs!$B$5)^2+(C7-Inputs!$B$6)^2) -> 337.28427 | D8: =SQRT((D6-Inputs!$B$5)^2+(D7-Inputs!$B$6)^2) -> 305.26593 | E8: mm | T8: -12 | U8: =SQRT(((Inputs!$B$11*COS(RADIANS(T8))-Inputs!$B$7*SIN(RADIANS(T8)))-Inputs!$B$5)^2+((Inputs!$B$11*SIN(RADIANS(T8))+Inputs!$B$7*COS(RADIANS(T8)))-Inputs!$B$6)^2) -> 372.4392 | V8: =Validation!$B$14 -> 302.08952 | W8: =Validation!$B$15 -> 372.47903 | X8: =ABS(Inputs!$B$5*(Inputs!$B$11*SIN(RADIANS(T8))+Inputs!$B$7*COS(RADIANS(T8)))-Inputs!$B$6*(Inputs!$B$11*COS(RADIANS(T8))-Inputs!$B$7*SIN(RADIANS(T8))))/U8 -> 158.70382
A9: Stroke from neutral | B9: =B8-$C$8 -> 29.560305 | C9: =C8-$C$8 -> 0 | D9: =D8-$C$8 -> -32.018339 | E9: mm | T9: -11 | U9: =SQRT(((Inputs!$B$11*COS(RADIANS(T9))-Inputs!$B$7*SIN(RADIANS(T9)))-Inputs!$B$5)^2+((Inputs!$B$11*SIN(RADIANS(T9))+Inputs!$B$7*COS(RADIANS(T9)))-Inputs!$B$6)^2) -> 369.65556 | V9: =Validation!$B$14 -> 302.08952 | W9: =Validation!$B$15 -> 372.47903 | X9: =ABS(Inputs!$B$5*(Inputs!$B$11*SIN(RADIANS(T9))+Inputs!$B$7*COS(RADIANS(T9)))-Inputs!$B$6*(Inputs!$B$11*COS(RADIANS(T9))-Inputs!$B$7*SIN(RADIANS(T9))))/U9 -> 160.27641
A10: Cross product Ax·Py − Ay·Px | B10: =Inputs!$B$5*B7-Inputs!$B$6*B6 -> -59368.56 | C10: =Inputs!$B$5*C7-Inputs!$B$6*C6 -> -59585.5 | D10: =Inputs!$B$5*D7-Inputs!$B$6*D6 -> -57991.964 | E10: mm^2 | T10: -10 | U10: =SQRT(((Inputs!$B$11*COS(RADIANS(T10))-Inputs!$B$7*SIN(RADIANS(T10)))-Inputs!$B$5)^2+((Inputs!$B$11*SIN(RADIANS(T10))+Inputs!$B$7*COS(RADIANS(T10)))-Inputs!$B$6)^2) -> 366.84458 | V10: =Validation!$B$14 -> 302.08952 | W10: =Validation!$B$15 -> 372.47903 | X10: =ABS(Inputs!$B$5*(Inputs!$B$11*SIN(RADIANS(T10))+Inputs!$B$7*COS(RADIANS(T10)))-Inputs!$B$6*(Inputs!$B$11*COS(RADIANS(T10))-Inputs!$B$7*SIN(RADIANS(T10))))/U10 -> 161.83573
A11: dL/dθ (moment arm, signed) | B11: =B10/B8 -> -161.83573 | C11: =C10/C8 -> -176.66255 | D11: =D10/D8 -> -189.97195 | E11: mm/rad | T11: -9 | U11: =SQRT(((Inputs!$B$11*COS(RADIANS(T11))-Inputs!$B$7*SIN(RADIANS(T11)))-Inputs!$B$5)^2+((Inputs!$B$11*SIN(RADIANS(T11))+Inputs!$B$7*COS(RADIANS(T11)))-Inputs!$B$6)^2) -> 364.0065 | V11: =Validation!$B$14 -> 302.08952 | W11: =Validation!$B$15 -> 372.47903 | X11: =ABS(Inputs!$B$5*(Inputs!$B$11*SIN(RADIANS(T11))+Inputs!$B$7*COS(RADIANS(T11)))-Inputs!$B$6*(Inputs!$B$11*COS(RADIANS(T11))-Inputs!$B$7*SIN(RADIANS(T11))))/U11 -> 163.38162
A12: Dot product A·P | B12: =Inputs!$B$5*B6+Inputs!$B$6*B7 -> -6443.3818 | C12: =Inputs!$B$5*C6+Inputs!$B$6*C7 -> 3963.75 | D12: =Inputs!$B$5*D6+Inputs!$B$6*D7 -> 14250.445 | E12: mm^2 | T12: -8 | U12: =SQRT(((Inputs!$B$11*COS(RADIANS(T12))-Inputs!$B$7*SIN(RADIANS(T12)))-Inputs!$B$5)^2+((Inputs!$B$11*SIN(RADIANS(T12))+Inputs!$B$7*COS(RADIANS(T12)))-Inputs!$B$6)^2) -> 361.14156 | V12: =Validation!$B$14 -> 302.08952 | W12: =Validation!$B$15 -> 372.47903 | X12: =ABS(Inputs!$B$5*(Inputs!$B$11*SIN(RADIANS(T12))+Inputs!$B$7*COS(RADIANS(T12)))-Inputs!$B$6*(Inputs!$B$11*COS(RADIANS(T12))-Inputs!$B$7*SIN(RADIANS(T12))))/U12 -> 164.9139
A13: d²L/dθ² | B13: =(B12-B11^2)/B8 -> -88.95916 | C13: =(C12-C11^2)/C8 -> -80.780247 | D13: =(D12-D11^2)/D8 -> -71.540561 | E13: mm/rad^2 | T13: -7 | U13: =SQRT(((Inputs!$B$11*COS(RADIANS(T13))-Inputs!$B$7*SIN(RADIANS(T13)))-Inputs!$B$5)^2+((Inputs!$B$11*SIN(RADIANS(T13))+Inputs!$B$7*COS(RADIANS(T13)))-Inputs!$B$6)^2) -> 358.25 | V13: =Validation!$B$14 -> 302.08952 | W13: =Validation!$B$15 -> 372.47903 | X13: =ABS(Inputs!$B$5*(Inputs!$B$11*SIN(RADIANS(T13))+Inputs!$B$7*COS(RADIANS(T13)))-Inputs!$B$6*(Inputs!$B$11*COS(RADIANS(T13))-Inputs!$B$7*SIN(RADIANS(T13))))/U13 -> 166.43243
A14: Gimbal rate ω | B14: =RADIANS(Inputs!$B$14) -> 0.34906585 | C14: =RADIANS(Inputs!$B$14) -> 0.34906585 | D14: =RADIANS(Inputs!$B$14) -> 0.34906585 | E14: rad/s | T14: -6 | U14: =SQRT(((Inputs!$B$11*COS(RADIANS(T14))-Inputs!$B$7*SIN(RADIANS(T14)))-Inputs!$B$5)^2+((Inputs!$B$11*SIN(RADIANS(T14))+Inputs!$B$7*COS(RADIANS(T14)))-Inputs!$B$6)^2) -> 355.33206 | V14: =Validation!$B$14 -> 302.08952 | W14: =Validation!$B$15 -> 372.47903 | X14: =ABS(Inputs!$B$5*(Inputs!$B$11*SIN(RADIANS(T14))+Inputs!$B$7*COS(RADIANS(T14)))-Inputs!$B$6*(Inputs!$B$11*COS(RADIANS(T14))-Inputs!$B$7*SIN(RADIANS(T14))))/U14 -> 167.93703
A15: Gimbal angular accel α | B15: =RADIANS(Inputs!$B$15) -> 0.52359878 | C15: =RADIANS(Inputs!$B$15) -> 0.52359878 | D15: =RADIANS(Inputs!$B$15) -> 0.52359878 | E15: rad/s^2 | T15: -5 | U15: =SQRT(((Inputs!$B$11*COS(RADIANS(T15))-Inputs!$B$7*SIN(RADIANS(T15)))-Inputs!$B$5)^2+((Inputs!$B$11*SIN(RADIANS(T15))+Inputs!$B$7*COS(RADIANS(T15)))-Inputs!$B$6)^2) -> 352.38797 | V15: =Validation!$B$14 -> 302.08952 | W15: =Validation!$B$15 -> 372.47903 | X15: =ABS(Inputs!$B$5*(Inputs!$B$11*SIN(RADIANS(T15))+Inputs!$B$7*COS(RADIANS(T15)))-Inputs!$B$6*(Inputs!$B$11*COS(RADIANS(T15))-Inputs!$B$7*SIN(RADIANS(T15))))/U15 -> 169.42753
A16: Actuator speed |dL/dθ|·ω | B16: =ABS(B11)*B14 -> 56.491327 | C16: =ABS(C11)*C14 -> 61.666863 | D16: =ABS(D11)*D14 -> 66.31272 | E16: mm/s | T16: -4 | U16: =SQRT(((Inputs!$B$11*COS(RADIANS(T16))-Inputs!$B$7*SIN(RADIANS(T16)))-Inputs!$B$5)^2+((Inputs!$B$11*SIN(RADIANS(T16))+Inputs!$B$7*COS(RADIANS(T16)))-Inputs!$B$6)^2) -> 349.418 | V16: =Validation!$B$14 -> 302.08952 | W16: =Validation!$B$15 -> 372.47903 | X16: =ABS(Inputs!$B$5*(Inputs!$B$11*SIN(RADIANS(T16))+Inputs!$B$7*COS(RADIANS(T16)))-Inputs!$B$6*(Inputs!$B$11*COS(RADIANS(T16))-Inputs!$B$7*SIN(RADIANS(T16))))/U16 -> 170.90376
A17: Actuator accel, worst |d²L/dθ²|·ω² + |dL/dθ|·α | B17: =ABS(B13)*B14^2+ABS(B11)*B15 -> 95.576394 | C17: =ABS(C13)*C14^2+ABS(C11)*C15 -> 102.34312 | D17: =ABS(D13)*D14^2+ABS(D11)*D15 -> 108.18608 | E17: mm/s^2 | T17: -3 | U17: =SQRT(((Inputs!$B$11*COS(RADIANS(T17))-Inputs!$B$7*SIN(RADIANS(T17)))-Inputs!$B$5)^2+((Inputs!$B$11*SIN(RADIANS(T17))+Inputs!$B$7*COS(RADIANS(T17)))-Inputs!$B$6)^2) -> 346.42239 | V17: =Validation!$B$14 -> 302.08952 | W17: =Validation!$B$15 -> 372.47903 | X17: =ABS(Inputs!$B$5*(Inputs!$B$11*SIN(RADIANS(T17))+Inputs!$B$7*COS(RADIANS(T17)))-Inputs!$B$6*(Inputs!$B$11*COS(RADIANS(T17))-Inputs!$B$7*SIN(RADIANS(T17))))/U17 -> 172.36555
T18: -2 | U18: =SQRT(((Inputs!$B$11*COS(RADIANS(T18))-Inputs!$B$7*SIN(RADIANS(T18)))-Inputs!$B$5)^2+((Inputs!$B$11*SIN(RADIANS(T18))+Inputs!$B$7*COS(RADIANS(T18)))-Inputs!$B$6)^2) -> 343.4014 | V18: =Validation!$B$14 -> 302.08952 | W18: =Validation!$B$15 -> 372.47903 | X18: =ABS(Inputs!$B$5*(Inputs!$B$11*SIN(RADIANS(T18))+Inputs!$B$7*COS(RADIANS(T18)))-Inputs!$B$6*(Inputs!$B$11*COS(RADIANS(T18))-Inputs!$B$7*SIN(RADIANS(T18))))/U18 -> 173.81273
T19: -1 | U19: =SQRT(((Inputs!$B$11*COS(RADIANS(T19))-Inputs!$B$7*SIN(RADIANS(T19)))-Inputs!$B$5)^2+((Inputs!$B$11*SIN(RADIANS(T19))+Inputs!$B$7*COS(RADIANS(T19)))-Inputs!$B$6)^2) -> 340.35527 | V19: =Validation!$B$14 -> 302.08952 | W19: =Validation!$B$15 -> 372.47903 | X19: =ABS(Inputs!$B$5*(Inputs!$B$11*SIN(RADIANS(T19))+Inputs!$B$7*COS(RADIANS(T19)))-Inputs!$B$6*(Inputs!$B$11*COS(RADIANS(T19))-Inputs!$B$7*SIN(RADIANS(T19))))/U19 -> 175.24513
A20: Summary (per actuator) | T20: 0 | U20: =SQRT(((Inputs!$B$11*COS(RADIANS(T20))-Inputs!$B$7*SIN(RADIANS(T20)))-Inputs!$B$5)^2+((Inputs!$B$11*SIN(RADIANS(T20))+Inputs!$B$7*COS(RADIANS(T20)))-Inputs!$B$6)^2) -> 337.28427 | V20: =Validation!$B$14 -> 302.08952 | W20: =Validation!$B$15 -> 372.47903 | X20: =ABS(Inputs!$B$5*(Inputs!$B$11*SIN(RADIANS(T20))+Inputs!$B$7*COS(RADIANS(T20)))-Inputs!$B$6*(Inputs!$B$11*COS(RADIANS(T20))-Inputs!$B$7*SIN(RADIANS(T20))))/U20 -> 176.66255
A21: Required actuator speed (max) | B21: =MAX(B16:D16) -> 66.31272 | C21: mm/s | T21: 1 | U21: =SQRT(((Inputs!$B$11*COS(RADIANS(T21))-Inputs!$B$7*SIN(RADIANS(T21)))-Inputs!$B$5)^2+((Inputs!$B$11*SIN(RADIANS(T21))+Inputs!$B$7*COS(RADIANS(T21)))-Inputs!$B$6)^2) -> 334.18867 | V21: =Validation!$B$14 -> 302.08952 | W21: =Validation!$B$15 -> 372.47903 | X21: =ABS(Inputs!$B$5*(Inputs!$B$11*SIN(RADIANS(T21))+Inputs!$B$7*COS(RADIANS(T21)))-Inputs!$B$6*(Inputs!$B$11*COS(RADIANS(T21))-Inputs!$B$7*SIN(RADIANS(T21))))/U21 -> 178.06483
A22: Required actuator accel (max) | B22: =MAX(B17:D17) -> 108.18608 | C22: mm/s^2 | T22: 2 | U22: =SQRT(((Inputs!$B$11*COS(RADIANS(T22))-Inputs!$B$7*SIN(RADIANS(T22)))-Inputs!$B$5)^2+((Inputs!$B$11*SIN(RADIANS(T22))+Inputs!$B$7*COS(RADIANS(T22)))-Inputs!$B$6)^2) -> 331.06873 | V22: =Validation!$B$14 -> 302.08952 | W22: =Validation!$B$15 -> 372.47903 | X22: =ABS(Inputs!$B$5*(Inputs!$B$11*SIN(RADIANS(T22))+Inputs!$B$7*COS(RADIANS(T22)))-Inputs!$B$6*(Inputs!$B$11*COS(RADIANS(T22))-Inputs!$B$7*SIN(RADIANS(T22))))/U22 -> 179.45177
A23: Stroke used over ± required angle | B23: =MAX(B8:D8)-MIN(B8:D8) -> 61.578644 | C23: mm | T23: 3 | U23: =SQRT(((Inputs!$B$11*COS(RADIANS(T23))-Inputs!$B$7*SIN(RADIANS(T23)))-Inputs!$B$5)^2+((Inputs!$B$11*SIN(RADIANS(T23))+Inputs!$B$7*COS(RADIANS(T23)))-Inputs!$B$6)^2) -> 327.92471 | V23: =Validation!$B$14 -> 302.08952 | W23: =Validation!$B$15 -> 372.47903 | X23: =ABS(Inputs!$B$5*(Inputs!$B$11*SIN(RADIANS(T23))+Inputs!$B$7*COS(RADIANS(T23)))-Inputs!$B$6*(Inputs!$B$11*COS(RADIANS(T23))-Inputs!$B$7*SIN(RADIANS(T23))))/U23 -> 180.82319
A24: Smallest moment arm | B24: =MIN(ABS(B11),ABS(C11),ABS(D11)) -> 161.83573 | C24: mm/rad | T24: 4 | U24: =SQRT(((Inputs!$B$11*COS(RADIANS(T24))-Inputs!$B$7*SIN(RADIANS(T24)))-Inputs!$B$5)^2+((Inputs!$B$11*SIN(RADIANS(T24))+Inputs!$B$7*COS(RADIANS(T24)))-Inputs!$B$6)^2) -> 324.7569 | V24: =Validation!$B$14 -> 302.08952 | W24: =Validation!$B$15 -> 372.47903 | X24: =ABS(Inputs!$B$5*(Inputs!$B$11*SIN(RADIANS(T24))+Inputs!$B$7*COS(RADIANS(T24)))-Inputs!$B$6*(Inputs!$B$11*COS(RADIANS(T24))-Inputs!$B$7*SIN(RADIANS(T24))))/U24 -> 182.1789
A25: Shortest pin-to-pin length | B25: =MIN(B8:D8) -> 305.26593 | C25: mm | T25: 5 | U25: =SQRT(((Inputs!$B$11*COS(RADIANS(T25))-Inputs!$B$7*SIN(RADIANS(T25)))-Inputs!$B$5)^2+((Inputs!$B$11*SIN(RADIANS(T25))+Inputs!$B$7*COS(RADIANS(T25)))-Inputs!$B$6)^2) -> 321.56556 | V25: =Validation!$B$14 -> 302.08952 | W25: =Validation!$B$15 -> 372.47903 | X25: =ABS(Inputs!$B$5*(Inputs!$B$11*SIN(RADIANS(T25))+Inputs!$B$7*COS(RADIANS(T25)))-Inputs!$B$6*(Inputs!$B$11*COS(RADIANS(T25))-Inputs!$B$7*SIN(RADIANS(T25))))/U25 -> 183.51871
A26: Longest pin-to-pin length | B26: =MAX(B8:D8) -> 366.84458 | C26: mm | T26: 6 | U26: =SQRT(((Inputs!$B$11*COS(RADIANS(T26))-Inputs!$B$7*SIN(RADIANS(T26)))-Inputs!$B$5)^2+((Inputs!$B$11*SIN(RADIANS(T26))+Inputs!$B$7*COS(RADIANS(T26)))-Inputs!$B$6)^2) -> 318.35098 | V26: =Validation!$B$14 -> 302.08952 | W26: =Validation!$B$15 -> 372.47903 | X26: =ABS(Inputs!$B$5*(Inputs!$B$11*SIN(RADIANS(T26))+Inputs!$B$7*COS(RADIANS(T26)))-Inputs!$B$6*(Inputs!$B$11*COS(RADIANS(T26))-Inputs!$B$7*SIN(RADIANS(T26))))/U26 -> 184.8424
T27: 7 | U27: =SQRT(((Inputs!$B$11*COS(RADIANS(T27))-Inputs!$B$7*SIN(RADIANS(T27)))-Inputs!$B$5)^2+((Inputs!$B$11*SIN(RADIANS(T27))+Inputs!$B$7*COS(RADIANS(T27)))-Inputs!$B$6)^2) -> 315.11344 | V27: =Validation!$B$14 -> 302.08952 | W27: =Validation!$B$15 -> 372.47903 | X27: =ABS(Inputs!$B$5*(Inputs!$B$11*SIN(RADIANS(T27))+Inputs!$B$7*COS(RADIANS(T27)))-Inputs!$B$6*(Inputs!$B$11*COS(RADIANS(T27))-Inputs!$B$7*SIN(RADIANS(T27))))/U27 -> 186.14979
A28: Pass / fail checks and max achievable angle are on the Validation tab. | T28: 8 | U28: =SQRT(((Inputs!$B$11*COS(RADIANS(T28))-Inputs!$B$7*SIN(RADIANS(T28)))-Inputs!$B$5)^2+((Inputs!$B$11*SIN(RADIANS(T28))+Inputs!$B$7*COS(RADIANS(T28)))-Inputs!$B$6)^2) -> 311.85322 | V28: =Validation!$B$14 -> 302.08952 | W28: =Validation!$B$15 -> 372.47903 | X28: =ABS(Inputs!$B$5*(Inputs!$B$11*SIN(RADIANS(T28))+Inputs!$B$7*COS(RADIANS(T28)))-Inputs!$B$6*(Inputs!$B$11*COS(RADIANS(T28))-Inputs!$B$7*SIN(RADIANS(T28))))/U28 -> 187.44065
T29: 9 | U29: =SQRT(((Inputs!$B$11*COS(RADIANS(T29))-Inputs!$B$7*SIN(RADIANS(T29)))-Inputs!$B$5)^2+((Inputs!$B$11*SIN(RADIANS(T29))+Inputs!$B$7*COS(RADIANS(T29)))-Inputs!$B$6)^2) -> 308.57062 | V29: =Validation!$B$14 -> 302.08952 | W29: =Validation!$B$15 -> 372.47903 | X29: =ABS(Inputs!$B$5*(Inputs!$B$11*SIN(RADIANS(T29))+Inputs!$B$7*COS(RADIANS(T29)))-Inputs!$B$6*(Inputs!$B$11*COS(RADIANS(T29))-Inputs!$B$7*SIN(RADIANS(T29))))/U29 -> 188.71478
T30: 10 | U30: =SQRT(((Inputs!$B$11*COS(RADIANS(T30))-Inputs!$B$7*SIN(RADIANS(T30)))-Inputs!$B$5)^2+((Inputs!$B$11*SIN(RADIANS(T30))+Inputs!$B$7*COS(RADIANS(T30)))-Inputs!$B$6)^2) -> 305.26593 | V30: =Validation!$B$14 -> 302.08952 | W30: =Validation!$B$15 -> 372.47903 | X30: =ABS(Inputs!$B$5*(Inputs!$B$11*SIN(RADIANS(T30))+Inputs!$B$7*COS(RADIANS(T30)))-Inputs!$B$6*(Inputs!$B$11*COS(RADIANS(T30))-Inputs!$B$7*SIN(RADIANS(T30))))/U30 -> 189.97195
T31: 11 | U31: =SQRT(((Inputs!$B$11*COS(RADIANS(T31))-Inputs!$B$7*SIN(RADIANS(T31)))-Inputs!$B$5)^2+((Inputs!$B$11*SIN(RADIANS(T31))+Inputs!$B$7*COS(RADIANS(T31)))-Inputs!$B$6)^2) -> 301.93945 | V31: =Validation!$B$14 -> 302.08952 | W31: =Validation!$B$15 -> 372.47903 | X31: =ABS(Inputs!$B$5*(Inputs!$B$11*SIN(RADIANS(T31))+Inputs!$B$7*COS(RADIANS(T31)))-Inputs!$B$6*(Inputs!$B$11*COS(RADIANS(T31))-Inputs!$B$7*SIN(RADIANS(T31))))/U31 -> 191.21194
T32: 12 | U32: =SQRT(((Inputs!$B$11*COS(RADIANS(T32))-Inputs!$B$7*SIN(RADIANS(T32)))-Inputs!$B$5)^2+((Inputs!$B$11*SIN(RADIANS(T32))+Inputs!$B$7*COS(RADIANS(T32)))-Inputs!$B$6)^2) -> 298.59148 | V32: =Validation!$B$14 -> 302.08952 | W32: =Validation!$B$15 -> 372.47903 | X32: =ABS(Inputs!$B$5*(Inputs!$B$11*SIN(RADIANS(T32))+Inputs!$B$7*COS(RADIANS(T32)))-Inputs!$B$6*(Inputs!$B$11*COS(RADIANS(T32))-Inputs!$B$7*SIN(RADIANS(T32))))/U32 -> 192.43451
T33: 13 | U33: =SQRT(((Inputs!$B$11*COS(RADIANS(T33))-Inputs!$B$7*SIN(RADIANS(T33)))-Inputs!$B$5)^2+((Inputs!$B$11*SIN(RADIANS(T33))+Inputs!$B$7*COS(RADIANS(T33)))-Inputs!$B$6)^2) -> 295.22232 | V33: =Validation!$B$14 -> 302.08952 | W33: =Validation!$B$15 -> 372.47903 | X33: =ABS(Inputs!$B$5*(Inputs!$B$11*SIN(RADIANS(T33))+Inputs!$B$7*COS(RADIANS(T33)))-Inputs!$B$6*(Inputs!$B$11*COS(RADIANS(T33))-Inputs!$B$7*SIN(RADIANS(T33))))/U33 -> 193.63941
T34: 14 | U34: =SQRT(((Inputs!$B$11*COS(RADIANS(T34))-Inputs!$B$7*SIN(RADIANS(T34)))-Inputs!$B$5)^2+((Inputs!$B$11*SIN(RADIANS(T34))+Inputs!$B$7*COS(RADIANS(T34)))-Inputs!$B$6)^2) -> 291.83229 | V34: =Validation!$B$14 -> 302.08952 | W34: =Validation!$B$15 -> 372.47903 | X34: =ABS(Inputs!$B$5*(Inputs!$B$11*SIN(RADIANS(T34))+Inputs!$B$7*COS(RADIANS(T34)))-Inputs!$B$6*(Inputs!$B$11*COS(RADIANS(T34))-Inputs!$B$7*SIN(RADIANS(T34))))/U34 -> 194.82641
T35: 15 | U35: =SQRT(((Inputs!$B$11*COS(RADIANS(T35))-Inputs!$B$7*SIN(RADIANS(T35)))-Inputs!$B$5)^2+((Inputs!$B$11*SIN(RADIANS(T35))+Inputs!$B$7*COS(RADIANS(T35)))-Inputs!$B$6)^2) -> 288.4217 | V35: =Validation!$B$14 -> 302.08952 | W35: =Validation!$B$15 -> 372.47903 | X35: =ABS(Inputs!$B$5*(Inputs!$B$11*SIN(RADIANS(T35))+Inputs!$B$7*COS(RADIANS(T35)))-Inputs!$B$6*(Inputs!$B$11*COS(RADIANS(T35))-Inputs!$B$7*SIN(RADIANS(T35))))/U35 -> 195.99523

Sheet Loads
A1: Gimbal torques and actuator forces
A3: Derived | T3: Chart data (auto)
A4: Thrust | B4: =Inputs!$B$17*Inputs!$B$63 -> 8896.44 | C4: N | U4: Required (× margin) | V4: Selected actuator rating
A5: Engine-side mass | B5: =Inputs!$B$18*Inputs!$B$64 -> 9.07184 | C5: kg | T5: Running | U5: =B34 -> 1063.4512 | V5: =Validation!B28 -> 2000
A6: Inertia about gimbal m·d² + m·L²/12 | B6: =B5*(Inputs!$B$19/1000)^2+B5*(Inputs!$B$21/1000)^2/12 -> 0.3477296 | C6: kg*m^2 | T6: Holding | U6: =B35 -> 3158.1329 | V6: =Validation!B29 -> 6010
A8: Running load (moving) | B8: Min angle | C8: Neutral | D8: Max angle | E8: Unit
A9: Gimbal angle | B9: =Geometry!B4 -> -10 | C9: =Geometry!C4 -> 0 | D9: =Geometry!D4 -> 10 | E9: deg
A10: Inertia I·α | B10: =$B$6*Geometry!B15 -> 0.18207079 | C10: =$B$6*Geometry!C15 -> 0.18207079 | D10: =$B$6*Geometry!D15 -> 0.18207079 | E10: N*m
A11: Pendulum m·a·d·sin|θ| | B11: =$B$5*Inputs!$B$22*Inputs!$B$62*(Inputs!$B$19/1000)*SIN(ABS(Geometry!B5)) -> 12.54588 | C11: =$B$5*Inputs!$B$22*Inputs!$B$62*(Inputs!$B$19/1000)*SIN(ABS(Geometry!C5)) -> 0 | D11: =$B$5*Inputs!$B$22*Inputs!$B$62*(Inputs!$B$19/1000)*SIN(ABS(Geometry!D5)) -> 12.54588 | E11: N*m
A12: Bearing friction μ·T·r_b | B12: =Inputs!$B$25*$B$4*Inputs!$B$24/1000 -> 16.947718 | C12: =Inputs!$B$25*$B$4*Inputs!$B$24/1000 -> 16.947718 | D12: =Inputs!$B$25*$B$4*Inputs!$B$24/1000 -> 16.947718 | E12: N*m
A13: Misalignment, offset T·e | B13: =$B$4*Inputs!$B$26/1000 -> 13.34466 | C13: =$B$4*Inputs!$B$26/1000 -> 13.34466 | D13: =$B$4*Inputs!$B$26/1000 -> 13.34466 | E13: N*m
A14: Misalignment, angle T·sinδ·d_throat | B14: =$B$4*SIN(RADIANS(Inputs!$B$27))*Inputs!$B$20/1000 -> 21.715935 | C14: =$B$4*SIN(RADIANS(Inputs!$B$27))*Inputs!$B$20/1000 -> 21.715935 | D14: =$B$4*SIN(RADIANS(Inputs!$B$27))*Inputs!$B$20/1000 -> 21.715935 | E14: N*m
A15: Hose (linear in angle) | B15: =Inputs!$B$29*ABS(B9)/Inputs!$B$13 -> 50 | C15: =Inputs!$B$29*ABS(C9)/Inputs!$B$13 -> 0 | D15: =Inputs!$B$29*ABS(D9)/Inputs!$B$13 -> 50 | E15: N*m
A16: Running torque total | B16: =SUM(B10:B15) -> 114.73626 | C16: =SUM(C10:C15) -> 52.190384 | D16: =SUM(D10:D15) -> 114.73626 | E16: N*m
A17: Moment arm |dL/dθ| | B17: =ABS(Geometry!B11)/1000 -> 0.16183573 | C17: =ABS(Geometry!C11)/1000 -> 0.17666255 | D17: =ABS(Geometry!D11)/1000 -> 0.18997195 | E17: m/rad
A18: Running force | B18: =B16/B17 -> 708.96744 | C18: =C16/C17 -> 295.42415 | D18: =D16/D17 -> 603.96424 | E18: N
A19: Running force × margin | B19: =B18*Inputs!$B$30 -> 1063.4512 | C19: =C18*Inputs!$B$30 -> 443.13622 | D19: =D18*Inputs!$B$30 -> 905.94636 | E19: N
A20: Running force × margin | B20: =B19/Inputs!$B$63 -> 239.07342 | C20: =C19/Inputs!$B$63 -> 99.621022 | D20: =D19/Inputs!$B$63 -> 203.66492 | E20: lbf
A23: Holding load (startup, at neutral) | B23: Value | C23: Unit
A24: Startup side load torque f·T·d_exit | B24: =Inputs!$B$28*$B$4*Inputs!$B$21/1000 -> 336.88861 | C24: N*m
A25: Misalignment (offset + angle) | B25: =C13+C14 -> 35.060595 | C25: N*m
A26: Holding torque total | B26: =B24+B25 -> 371.94921 | C26: N*m
A27: Moment arm at neutral | B27: =C17 -> 0.17666255 | C27: m/rad
A28: Holding force | B28: =B26/B27 -> 2105.4219 | C28: N
A29: Holding force × margin | B29: =B28*Inputs!$B$30 -> 3158.1329 | C29: N
A30: Holding force × margin | B30: =B29/Inputs!$B$63 -> 709.97677 | C30: lbf
A31: Friction is left out of holding: it resists motion, so omitting it is conservative.
A33: Summary (per actuator)
A34: Worst running force × margin | B34: =MAX(B19:D19) -> 1063.4512 | C34: N | D34: =MAX(B20:D20) -> 239.07342 | E34: lbf
A35: Holding force × margin | B35: =B29 -> 3158.1329 | C35: N | D35: =B30 -> 709.97677 | E35: lbf
A36: Required speed | B36: =Geometry!B21 -> 66.31272 | C36: mm/s

Sheet Validation
A1: Geometry validation and max achievable angle
A2: Checks the one design on Inputs. Angle search: 0.25° steps out to 30° each way, one axis at a time (table from row 42).
X3: Chart data (auto)
A4: Actuator travel | B4: Value | C4: Unit | X4: Angle (deg) | Y4: Envelope radius | Z4: 6 in limit | AA4: Clearance margin | AB4: Zero
A5: Actuator | B5: =Inputs!$B$32 -> IMA33-RN04 (1-stack) | X5: -15 | Y5: =IF(X5<0,INDEX($N$43:$N$163,MATCH(-X5,$A$43:$A$163,0)),INDEX($H$43:$H$163,MATCH(X5,$A$43:$A$163,0))) -> 291.8 | Z5: =Inputs!$B$38 -> 350 | AA5: =IF(X5<0,INDEX($O$43:$O$163,MATCH(-X5,$A$43:$A$163,0)),INDEX($I$43:$I$163,MATCH(X5,$A$43:$A$163,0))) -> 5.8459578 | AB5: 0
A6: Dead length (retracted − stroke) | B6: {=INDEX(Actuators!$W$2:$W$20,MATCH(Inputs!$B$32,Actuators!$A$2:$A$20,0))} -> 216.7 | C6: mm | X6: -14.5 | Y6: =IF(X6<0,INDEX($N$43:$N$163,MATCH(-X6,$A$43:$A$163,0)),INDEX($H$43:$H$163,MATCH(X6,$A$43:$A$163,0))) -> 291.8 | Z6: =Inputs!$B$38 -> 350 | AA6: =IF(X6<0,INDEX($O$43:$O$163,MATCH(-X6,$A$43:$A$163,0)),INDEX($I$43:$I$163,MATCH(X6,$A$43:$A$163,0))) -> 6.5076983 | AB6: 0
A7: Body width | B7: {=INDEX(Actuators!$J$2:$J$20,MATCH(Inputs!$B$32,Actuators!$A$2:$A$20,0))} -> 83.6 | C7: mm | X7: -14 | Y7: =IF(X7<0,INDEX($N$43:$N$163,MATCH(-X7,$A$43:$A$163,0)),INDEX($H$43:$H$163,MATCH(X7,$A$43:$A$163,0))) -> 291.8 | Z7: =Inputs!$B$38 -> 350 | AA7: =IF(X7<0,INDEX($O$43:$O$163,MATCH(-X7,$A$43:$A$163,0)),INDEX($I$43:$I$163,MATCH(X7,$A$43:$A$163,0))) -> 7.1687764 | AB7: 0
A8: Rod diameter | B8: {=INDEX(Actuators!$M$2:$M$20,MATCH(Inputs!$B$32,Actuators!$A$2:$A$20,0))} -> 30.13 | C8: mm | X8: -13.5 | Y8: =IF(X8<0,INDEX($N$43:$N$163,MATCH(-X8,$A$43:$A$163,0)),INDEX($H$43:$H$163,MATCH(X8,$A$43:$A$163,0))) -> 291.8 | Z8: =Inputs!$B$38 -> 350 | AA8: =IF(X8<0,INDEX($O$43:$O$163,MATCH(-X8,$A$43:$A$163,0)),INDEX($I$43:$I$163,MATCH(X8,$A$43:$A$163,0))) -> 7.8291816 | AB8: 0
A9: Catalog stroke range | B9: {=INDEX(Actuators!$U$2:$U$20,MATCH(Inputs!$B$32,Actuators!$A$2:$A$20,0))&" – "&INDEX(Actuators!$V$2:$V$20,MATCH(Inputs!$B$32,Actuators!$A$2:$A$20,0))} -> 76.2 – 457.2 | C9: mm | X9: -13 | Y9: =IF(X9<0,INDEX($N$43:$N$163,MATCH(-X9,$A$43:$A$163,0)),INDEX($H$43:$H$163,MATCH(X9,$A$43:$A$163,0))) -> 291.8 | Z9: =Inputs!$B$38 -> 350 | AA9: =IF(X9<0,INDEX($O$43:$O$163,MATCH(-X9,$A$43:$A$163,0)),INDEX($I$43:$I$163,MATCH(X9,$A$43:$A$163,0))) -> 8.4889035 | AB9: 0
A10: Pin-to-pin length at neutral | B10: =Geometry!C8 -> 337.28427 | C10: mm | X10: -12.5 | Y10: =IF(X10<0,INDEX($N$43:$N$163,MATCH(-X10,$A$43:$A$163,0)),INDEX($H$43:$H$163,MATCH(X10,$A$43:$A$163,0))) -> 291.8 | Z10: =Inputs!$B$38 -> 350 | AA10: =IF(X10<0,INDEX($O$43:$O$163,MATCH(-X10,$A$43:$A$163,0)),INDEX($I$43:$I$163,MATCH(X10,$A$43:$A$163,0))) -> 9.1479318 | AB10: 0
A11: Stroke used | B11: {=IF(Inputs!$B$33>0,Inputs!$B$33,MIN(INDEX(Actuators!$V$2:$V$20,MATCH(Inputs!$B$32,Actuators!$A$2:$A$20,0)),MAX(INDEX(Actuators!$U$2:$U$20,MATCH(Inputs!$B$32,Actuators!$A$2:$A$20,0)),(B10-B6-Inputs!$B$35)/1.5)))} -> 80.389516 | C11: mm | X11: -12 | Y11: =IF(X11<0,INDEX($N$43:$N$163,MATCH(-X11,$A$43:$A$163,0)),INDEX($H$43:$H$163,MATCH(X11,$A$43:$A$163,0))) -> 291.8 | Z11: =Inputs!$B$38 -> 350 | AA11: =IF(X11<0,INDEX($O$43:$O$163,MATCH(-X11,$A$43:$A$163,0)),INDEX($I$43:$I$163,MATCH(X11,$A$43:$A$163,0))) -> 9.806256 | AB11: 0
A12: Retracted pin-to-pin | B12: =B6+Inputs!$B$35+B11 -> 297.08952 | C12: mm | X12: -11.5 | Y12: =IF(X12<0,INDEX($N$43:$N$163,MATCH(-X12,$A$43:$A$163,0)),INDEX($H$43:$H$163,MATCH(X12,$A$43:$A$163,0))) -> 291.8 | Z12: =Inputs!$B$38 -> 350 | AA12: =IF(X12<0,INDEX($O$43:$O$163,MATCH(-X12,$A$43:$A$163,0)),INDEX($I$43:$I$163,MATCH(X12,$A$43:$A$163,0))) -> 10.463866 | AB12: 0
A13: Extended pin-to-pin | B13: =B6+Inputs!$B$35+2*B11 -> 377.47903 | C13: mm | X13: -11 | Y13: =IF(X13<0,INDEX($N$43:$N$163,MATCH(-X13,$A$43:$A$163,0)),INDEX($H$43:$H$163,MATCH(X13,$A$43:$A$163,0))) -> 291.8 | Z13: =Inputs!$B$38 -> 350 | AA13: =IF(X13<0,INDEX($O$43:$O$163,MATCH(-X13,$A$43:$A$163,0)),INDEX($I$43:$I$163,MATCH(X13,$A$43:$A$163,0))) -> 11.120751 | AB13: 0
A14: Usable length min (with overtravel margin) | B14: =B12+Inputs!$B$34 -> 302.08952 | C14: mm | X14: -10.5 | Y14: =IF(X14<0,INDEX($N$43:$N$163,MATCH(-X14,$A$43:$A$163,0)),INDEX($H$43:$H$163,MATCH(X14,$A$43:$A$163,0))) -> 291.8 | Z14: =Inputs!$B$38 -> 350 | AA14: =IF(X14<0,INDEX($O$43:$O$163,MATCH(-X14,$A$43:$A$163,0)),INDEX($I$43:$I$163,MATCH(X14,$A$43:$A$163,0))) -> 11.776901 | AB14: 0
A15: Usable length max (with overtravel margin) | B15: =B13-Inputs!$B$34 -> 372.47903 | C15: mm | X15: -10 | Y15: =IF(X15<0,INDEX($N$43:$N$163,MATCH(-X15,$A$43:$A$163,0)),INDEX($H$43:$H$163,MATCH(X15,$A$43:$A$163,0))) -> 291.8 | Z15: =Inputs!$B$38 -> 350 | AA15: =IF(X15<0,INDEX($O$43:$O$163,MATCH(-X15,$A$43:$A$163,0)),INDEX($I$43:$I$163,MATCH(X15,$A$43:$A$163,0))) -> 12.432307 | AB15: 0
A16: Body length from rear pin | B16: =B12-Inputs!$B$36 -> 257.08952 | C16: mm | X16: -9.5 | Y16: =IF(X16<0,INDEX($N$43:$N$163,MATCH(-X16,$A$43:$A$163,0)),INDEX($H$43:$H$163,MATCH(X16,$A$43:$A$163,0))) -> 291.8 | Z16: =Inputs!$B$38 -> 350 | AA16: =IF(X16<0,INDEX($O$43:$O$163,MATCH(-X16,$A$43:$A$163,0)),INDEX($I$43:$I$163,MATCH(X16,$A$43:$A$163,0))) -> 13.086957 | AB16: 0
X17: -9 | Y17: =IF(X17<0,INDEX($N$43:$N$163,MATCH(-X17,$A$43:$A$163,0)),INDEX($H$43:$H$163,MATCH(X17,$A$43:$A$163,0))) -> 291.8 | Z17: =Inputs!$B$38 -> 350 | AA17: =IF(X17<0,INDEX($O$43:$O$163,MATCH(-X17,$A$43:$A$163,0)),INDEX($I$43:$I$163,MATCH(X17,$A$43:$A$163,0))) -> 13.740842 | AB17: 0
A18: Max achievable angle | B18: Value | C18: Unit | X18: -8.5 | Y18: =IF(X18<0,INDEX($N$43:$N$163,MATCH(-X18,$A$43:$A$163,0)),INDEX($H$43:$H$163,MATCH(X18,$A$43:$A$163,0))) -> 291.8 | Z18: =Inputs!$B$38 -> 350 | AA18: =IF(X18<0,INDEX($O$43:$O$163,MATCH(-X18,$A$43:$A$163,0)),INDEX($I$43:$I$163,MATCH(X18,$A$43:$A$163,0))) -> 14.393952 | AB18: 0
A19: Max angle, positive direction | B19: {=IF(IFERROR(MATCH(0,$J$43:$J$163,0),0)=0,30,IF(IFERROR(MATCH(0,$J$43:$J$163,0),0)=1,0,INDEX($A$43:$A$163,IFERROR(MATCH(0,$J$43:$J$163,0),0)-1)))} -> 10.75 | C19: deg | X19: -8 | Y19: =IF(X19<0,INDEX($N$43:$N$163,MATCH(-X19,$A$43:$A$163,0)),INDEX($H$43:$H$163,MATCH(X19,$A$43:$A$163,0))) -> 291.8 | Z19: =Inputs!$B$38 -> 350 | AA19: =IF(X19<0,INDEX($O$43:$O$163,MATCH(-X19,$A$43:$A$163,0)),INDEX($I$43:$I$163,MATCH(X19,$A$43:$A$163,0))) -> 15.046276 | AB19: 0
A20: limited by | B20: {=IF(IFERROR(MATCH(0,$J$43:$J$163,0),0)=0,"none within 30°",IF(INDEX($G$43:$G$163,IFERROR(MATCH(0,$J$43:$J$163,0),0))<$B$14,"actuator fully retracted",IF(INDEX($G$43:$G$163,IFERROR(MATCH(0,$J$43:$J$163,0),0))>$B$15,"actuator fully extended",IF(INDEX($H$43:$H$163,IFERROR(MATCH(0,$J$43:$J$163,0),0))>Inputs!$B$38,"actuator past 6 in",IF(INDEX($I$43:$I$163,IFERROR(MATCH(0,$J$43:$J$163,0),0))<0,"actuator hits chamber","chamber/nozzle past 6 in")))))} -> actuator fully retracted | X20: -7.5 | Y20: =IF(X20<0,INDEX($N$43:$N$163,MATCH(-X20,$A$43:$A$163,0)),INDEX($H$43:$H$163,MATCH(X20,$A$43:$A$163,0))) -> 291.8 | Z20: =Inputs!$B$38 -> 350 | AA20: =IF(X20<0,INDEX($O$43:$O$163,MATCH(-X20,$A$43:$A$163,0)),INDEX($I$43:$I$163,MATCH(X20,$A$43:$A$163,0))) -> 15.697805 | AB20: 0
A21: Max angle, negative direction | B21: {=IF(IFERROR(MATCH(0,$P$43:$P$163,0),0)=0,30,IF(IFERROR(MATCH(0,$P$43:$P$163,0),0)=1,0,INDEX($A$43:$A$163,IFERROR(MATCH(0,$P$43:$P$163,0),0)-1)))} -> 12 | C21: deg | X21: -7 | Y21: =IF(X21<0,INDEX($N$43:$N$163,MATCH(-X21,$A$43:$A$163,0)),INDEX($H$43:$H$163,MATCH(X21,$A$43:$A$163,0))) -> 291.8 | Z21: =Inputs!$B$38 -> 350 | AA21: =IF(X21<0,INDEX($O$43:$O$163,MATCH(-X21,$A$43:$A$163,0)),INDEX($I$43:$I$163,MATCH(X21,$A$43:$A$163,0))) -> 16.348529 | AB21: 0
A22: limited by | B22: {=IF(IFERROR(MATCH(0,$P$43:$P$163,0),0)=0,"none within 30°",IF(INDEX($M$43:$M$163,IFERROR(MATCH(0,$P$43:$P$163,0),0))<$B$14,"actuator fully retracted",IF(INDEX($M$43:$M$163,IFERROR(MATCH(0,$P$43:$P$163,0),0))>$B$15,"actuator fully extended",IF(INDEX($N$43:$N$163,IFERROR(MATCH(0,$P$43:$P$163,0),0))>Inputs!$B$38,"actuator past 6 in",IF(INDEX($O$43:$O$163,IFERROR(MATCH(0,$P$43:$P$163,0),0))<0,"actuator hits chamber","chamber/nozzle past 6 in")))))} -> actuator fully extended | X22: -6.5 | Y22: =IF(X22<0,INDEX($N$43:$N$163,MATCH(-X22,$A$43:$A$163,0)),INDEX($H$43:$H$163,MATCH(X22,$A$43:$A$163,0))) -> 291.8 | Z22: =Inputs!$B$38 -> 350 | AA22: =IF(X22<0,INDEX($O$43:$O$163,MATCH(-X22,$A$43:$A$163,0)),INDEX($I$43:$I$163,MATCH(X22,$A$43:$A$163,0))) -> 16.998438 | AB22: 0
A23: Max symmetric angle (±) | B23: =MIN(B19,B21) -> 10.75 | C23: deg | X23: -6 | Y23: =IF(X23<0,INDEX($N$43:$N$163,MATCH(-X23,$A$43:$A$163,0)),INDEX($H$43:$H$163,MATCH(X23,$A$43:$A$163,0))) -> 291.8 | Z23: =Inputs!$B$38 -> 350 | AA23: =IF(X23<0,INDEX($O$43:$O$163,MATCH(-X23,$A$43:$A$163,0)),INDEX($I$43:$I$163,MATCH(X23,$A$43:$A$163,0))) -> 17.647523 | AB23: 0
X24: -5.5 | Y24: =IF(X24<0,INDEX($N$43:$N$163,MATCH(-X24,$A$43:$A$163,0)),INDEX($H$43:$H$163,MATCH(X24,$A$43:$A$163,0))) -> 291.8 | Z24: =Inputs!$B$38 -> 350 | AA24: =IF(X24<0,INDEX($O$43:$O$163,MATCH(-X24,$A$43:$A$163,0)),INDEX($I$43:$I$163,MATCH(X24,$A$43:$A$163,0))) -> 18.295773 | AB24: 0
A25: Validation check | B25: Design value | C25: Requirement | D25: Status | X25: -5 | Y25: =IF(X25<0,INDEX($N$43:$N$163,MATCH(-X25,$A$43:$A$163,0)),INDEX($H$43:$H$163,MATCH(X25,$A$43:$A$163,0))) -> 291.8 | Z25: =Inputs!$B$38 -> 350 | AA25: =IF(X25<0,INDEX($O$43:$O$163,MATCH(-X25,$A$43:$A$163,0)),INDEX($I$43:$I$163,MATCH(X25,$A$43:$A$163,0))) -> 18.943178 | AB25: 0
A26: Neutral length inside actuator travel | B26: =B10 -> 337.28427 | C26: =TEXT(B14,"0.0")&" – "&TEXT(B15,"0.0") -> 302.1 – 372.5 | D26: =IF(AND(B26>=B14,B26<=B15),"OK","FAIL") -> OK | X26: -4.5 | Y26: =IF(X26<0,INDEX($N$43:$N$163,MATCH(-X26,$A$43:$A$163,0)),INDEX($H$43:$H$163,MATCH(X26,$A$43:$A$163,0))) -> 291.8 | Z26: =Inputs!$B$38 -> 350 | AA26: =IF(X26<0,INDEX($O$43:$O$163,MATCH(-X26,$A$43:$A$163,0)),INDEX($I$43:$I$163,MATCH(X26,$A$43:$A$163,0))) -> 19.58973 | AB26: 0
A27: Max symmetric angle ≥ required | B27: =B23 -> 10.75 | C27: =Inputs!$B$13 -> 10 | D27: =IF(B27>=C27,"OK","FAIL") -> OK | X27: -4 | Y27: =IF(X27<0,INDEX($N$43:$N$163,MATCH(-X27,$A$43:$A$163,0)),INDEX($H$43:$H$163,MATCH(X27,$A$43:$A$163,0))) -> 291.8 | Z27: =Inputs!$B$38 -> 350 | AA27: =IF(X27<0,INDEX($O$43:$O$163,MATCH(-X27,$A$43:$A$163,0)),INDEX($I$43:$I$163,MATCH(X27,$A$43:$A$163,0))) -> 20.235418 | AB27: 0
A28: Continuous thrust ≥ running force × margin (N) | B28: {=INDEX(Actuators!$B$2:$B$20,MATCH(Inputs!$B$32,Actuators!$A$2:$A$20,0))*1000} -> 2000 | C28: =Loads!B34 -> 1063.4512 | D28: =IF(B28>=C28,"OK","FAIL") -> OK | X28: -3.5 | Y28: =IF(X28<0,INDEX($N$43:$N$163,MATCH(-X28,$A$43:$A$163,0)),INDEX($H$43:$H$163,MATCH(X28,$A$43:$A$163,0))) -> 291.8 | Z28: =Inputs!$B$38 -> 350 | AA28: =IF(X28<0,INDEX($O$43:$O$163,MATCH(-X28,$A$43:$A$163,0)),INDEX($I$43:$I$163,MATCH(X28,$A$43:$A$163,0))) -> 20.880234 | AB28: 0
A29: Peak thrust ≥ holding force × margin (N) | B29: {=INDEX(Actuators!$C$2:$C$20,MATCH(Inputs!$B$32,Actuators!$A$2:$A$20,0))*1000} -> 6010 | C29: =Loads!B35 -> 3158.1329 | D29: =IF(B29>=C29,"OK","FAIL") -> OK | X29: -3 | Y29: =IF(X29<0,INDEX($N$43:$N$163,MATCH(-X29,$A$43:$A$163,0)),INDEX($H$43:$H$163,MATCH(X29,$A$43:$A$163,0))) -> 291.8 | Z29: =Inputs!$B$38 -> 350 | AA29: =IF(X29<0,INDEX($O$43:$O$163,MATCH(-X29,$A$43:$A$163,0)),INDEX($I$43:$I$163,MATCH(X29,$A$43:$A$163,0))) -> 21.524166 | AB29: 0
A30: Max speed ≥ required (mm/s) | B30: {=INDEX(Actuators!$D$2:$D$20,MATCH(Inputs!$B$32,Actuators!$A$2:$A$20,0))} -> 244 | C30: =Geometry!B21 -> 66.31272 | D30: =IF(B30>=C30,"OK","FAIL") -> OK | X30: -2.5 | Y30: =IF(X30<0,INDEX($N$43:$N$163,MATCH(-X30,$A$43:$A$163,0)),INDEX($H$43:$H$163,MATCH(X30,$A$43:$A$163,0))) -> 291.8 | Z30: =Inputs!$B$38 -> 350 | AA30: =IF(X30<0,INDEX($O$43:$O$163,MATCH(-X30,$A$43:$A$163,0)),INDEX($I$43:$I$163,MATCH(X30,$A$43:$A$163,0))) -> 22.167207 | AB30: 0
A31: Actuator envelope at neutral ≤ 6 in (mm) | B31: =H43 -> 291.8 | C31: =Inputs!$B$38 -> 350 | D31: =IF(B31<=C31,"OK","FAIL") -> OK | X31: -2 | Y31: =IF(X31<0,INDEX($N$43:$N$163,MATCH(-X31,$A$43:$A$163,0)),INDEX($H$43:$H$163,MATCH(X31,$A$43:$A$163,0))) -> 291.8 | Z31: =Inputs!$B$38 -> 350 | AA31: =IF(X31<0,INDEX($O$43:$O$163,MATCH(-X31,$A$43:$A$163,0)),INDEX($I$43:$I$163,MATCH(X31,$A$43:$A$163,0))) -> 22.809346 | AB31: 0
A32: Clearance margin to chamber at neutral (mm) | B32: =I43 -> 25.368703 | C32: 0 | D32: =IF(B32>=C32,"OK","FAIL") -> OK | X32: -1.5 | Y32: =IF(X32<0,INDEX($N$43:$N$163,MATCH(-X32,$A$43:$A$163,0)),INDEX($H$43:$H$163,MATCH(X32,$A$43:$A$163,0))) -> 291.8 | Z32: =Inputs!$B$38 -> 350 | AA32: =IF(X32<0,INDEX($O$43:$O$163,MATCH(-X32,$A$43:$A$163,0)),INDEX($I$43:$I$163,MATCH(X32,$A$43:$A$163,0))) -> 23.450575 | AB32: 0
A33: Chamber / nozzle radius at required angle ≤ 6 in (mm) | B33: {=INDEX($C$43:$C$163,MATCH(Inputs!$B$13,$A$43:$A$163,1))} -> 147.02952 | C33: =Inputs!$B$38 -> 350 | D33: =IF(B33<=C33,"OK","FAIL") -> OK | X33: -1 | Y33: =IF(X33<0,INDEX($N$43:$N$163,MATCH(-X33,$A$43:$A$163,0)),INDEX($H$43:$H$163,MATCH(X33,$A$43:$A$163,0))) -> 291.8 | Z33: =Inputs!$B$38 -> 350 | AA33: =IF(X33<0,INDEX($O$43:$O$163,MATCH(-X33,$A$43:$A$163,0)),INDEX($I$43:$I$163,MATCH(X33,$A$43:$A$163,0))) -> 24.090883 | AB33: 0
A34: OVERALL | D34: =IF(COUNTIF(D26:D33,"FAIL")=0,"PASS","FAIL") -> PASS | X34: -0.5 | Y34: =IF(X34<0,INDEX($N$43:$N$163,MATCH(-X34,$A$43:$A$163,0)),INDEX($H$43:$H$163,MATCH(X34,$A$43:$A$163,0))) -> 291.8 | Z34: =Inputs!$B$38 -> 350 | AA34: =IF(X34<0,INDEX($O$43:$O$163,MATCH(-X34,$A$43:$A$163,0)),INDEX($I$43:$I$163,MATCH(X34,$A$43:$A$163,0))) -> 24.730262 | AB34: 0
X35: 0 | Y35: =IF(X35<0,INDEX($N$43:$N$163,MATCH(-X35,$A$43:$A$163,0)),INDEX($H$43:$H$163,MATCH(X35,$A$43:$A$163,0))) -> 291.8 | Z35: =Inputs!$B$38 -> 350 | AA35: =IF(X35<0,INDEX($O$43:$O$163,MATCH(-X35,$A$43:$A$163,0)),INDEX($I$43:$I$163,MATCH(X35,$A$43:$A$163,0))) -> 25.368703 | AB35: 0
A36: Clearance margin = distance from each chamber profile point to the actuator body (or rod, past the body) minus half-width and min clearance. Negative = interference. | X36: 0.5 | Y36: =IF(X36<0,INDEX($N$43:$N$163,MATCH(-X36,$A$43:$A$163,0)),INDEX($H$43:$H$163,MATCH(X36,$A$43:$A$163,0))) -> 291.8 | Z36: =Inputs!$B$38 -> 350 | AA36: =IF(X36<0,INDEX($O$43:$O$163,MATCH(-X36,$A$43:$A$163,0)),INDEX($I$43:$I$163,MATCH(X36,$A$43:$A$163,0))) -> 26.006196 | AB36: 0
A37: Envelope = outermost of the body (rear pin to body end, ± width/2) and the rod eye head at the chamber pin. | X37: 1 | Y37: =IF(X37<0,INDEX($N$43:$N$163,MATCH(-X37,$A$43:$A$163,0)),INDEX($H$43:$H$163,MATCH(X37,$A$43:$A$163,0))) -> 291.8 | Z37: =Inputs!$B$38 -> 350 | AA37: =IF(X37<0,INDEX($O$43:$O$163,MATCH(-X37,$A$43:$A$163,0)),INDEX($I$43:$I$163,MATCH(X37,$A$43:$A$163,0))) -> 26.642732 | AB37: 0
A38: Per-axis only. With both axes at max, total tilt is ~1.41× larger — check nozzle swing at that angle too. | X38: 1.5 | Y38: =IF(X38<0,INDEX($N$43:$N$163,MATCH(-X38,$A$43:$A$163,0)),INDEX($H$43:$H$163,MATCH(X38,$A$43:$A$163,0))) -> 291.8 | Z38: =Inputs!$B$38 -> 350 | AA38: =IF(X38<0,INDEX($O$43:$O$163,MATCH(-X38,$A$43:$A$163,0)),INDEX($I$43:$I$163,MATCH(X38,$A$43:$A$163,0))) -> 27.278303 | AB38: 0
X39: 2 | Y39: =IF(X39<0,INDEX($N$43:$N$163,MATCH(-X39,$A$43:$A$163,0)),INDEX($H$43:$H$163,MATCH(X39,$A$43:$A$163,0))) -> 291.8 | Z39: =Inputs!$B$38 -> 350 | AA39: =IF(X39<0,INDEX($O$43:$O$163,MATCH(-X39,$A$43:$A$163,0)),INDEX($I$43:$I$163,MATCH(X39,$A$43:$A$163,0))) -> 27.912898 | AB39: 0
X40: 2.5 | Y40: =IF(X40<0,INDEX($N$43:$N$163,MATCH(-X40,$A$43:$A$163,0)),INDEX($H$43:$H$163,MATCH(X40,$A$43:$A$163,0))) -> 291.8 | Z40: =Inputs!$B$38 -> 350 | AA40: =IF(X40<0,INDEX($O$43:$O$163,MATCH(-X40,$A$43:$A$163,0)),INDEX($I$43:$I$163,MATCH(X40,$A$43:$A$163,0))) -> 28.54651 | AB40: 0
...

Sheet CAD dims
A1: Final CAD dimensions and joint load checks
A2: Every dimension below is driven by Inputs, the selected actuator and the selected rod end. MS = margin of safety (allowable / actual − 1).
K3: Chart data (auto)
A4: 1. Design load at each pin | K4: =A23 -> Peak force vs holding × margin | L4: =IF(ISNUMBER(E23),MIN(E23,5),0) -> 0.90302316
A5: Item | B5: Value | C5: Unit | D5: Allowable / limit | E5: MS | F5: Status | G5: Note | K5: =A25 -> Continuous force vs running × margin | L5: =IF(ISNUMBER(E25),MIN(E25,5),0) -> 0.88066934
A6: Actuator peak force (the most it can push) | B6: {=INDEX(Actuators!$C$2:$C$20,MATCH(Inputs!$B$32,Actuators!$A$2:$A$20,0))*1000} -> 6010 | C6: N | K6: =A34 -> Static radial rating vs P | L6: =IF(ISNUMBER(E34),MIN(E34,5),0) -> 2.2168608
A7: Holding force × margin (startup side load) | B7: =Loads!B35 -> 3158.1329 | C7: N | K7: =A35 -> Shank thread tension, P / stress area | L7: =IF(ISNUMBER(E35),MIN(E35,5),0) -> 5
A8: Running force × margin | B8: =Loads!B34 -> 1063.4512 | C8: N | K8: =A36 -> Min thread engagement vs rod thread depth | L8: =IF(ISNUMBER(E36),MIN(E36,5),0) -> 0.85
A9: Limit load (largest of the three) | B9: =MAX(B6:B8) -> 6010 | C9: N | K9: =A37 -> Tilt available vs per-axis gimbal angle | L9: =IF(ISNUMBER(E37),MIN(E37,5),0) -> 0
A10: Design load P = limit × structural FoS | B10: =B9*Inputs!$B$44 -> 9015 | C10: N | K10: =A43 -> Double shear, P / (2·πd²/4) | L10: =IF(ISNUMBER(E43),MIN(E43,5),0) -> 5
A11: Per chamber lug (clevis splits it), P / 2 | B11: =B10/2 -> 4507.5 | C11: N | K11: =A44 -> Bending, M = (P/2)(t/2 + g/4), σ = 32M/(πd³) | L11: =IF(ISNUMBER(E44),MIN(E44,5),0) -> 4.7008753
K12: =A52 -> Bearing, (P/2) / (d·t) | L12: =IF(ISNUMBER(E52),MIN(E52,5),0) -> 4.6216306
A13: 2. Actuator | K13: =A53 -> Shear-out, (P/2) / (2·a·t) | L13: =IF(ISNUMBER(E53),MIN(E53,5),0) -> 3.000016
A14: Item | B14: Value | C14: Unit | D14: Allowable / limit | E14: MS | F14: Status | G14: Note | K14: =A54 -> Net section, (P/2) / ((w − d)·t) | L14: =IF(ISNUMBER(E54),MIN(E54,5),0) -> 5
A15: Model | B15: =Inputs!$B$32 -> IMA33-RN04 (1-stack) | K15: =A55 -> Root bending, 6·(P/2)·h / (t·L²) | L15: =IF(ISNUMBER(E55),MIN(E55,5),0) -> 3.0365557
A16: Stroke to order | B16: =Validation!B11 -> 80.389516 | C16: mm | G16: Validation tab; round to an orderable catalog stroke | K16: =A57 -> Rod eye head clearance to pad | L16: =IF(ISNUMBER(E57),MIN(E57,5),0) -> 3
A17: Retracted pin-to-pin | B17: =Validation!B12 -> 297.08952 | C17: mm | K17: =A66 -> Rear pin double shear | L17: =IF(ISNUMBER(E66),MIN(E66,5),0) -> 5
A18: Extended pin-to-pin | B18: =Validation!B13 -> 377.47903 | C18: mm | K18: =A67 -> Tongue bearing, P / (d·t) | L18: =IF(ISNUMBER(E67),MIN(E67,5),0) -> 3.9723794
A19: Neutral pin-to-pin | B19: =Validation!B10 -> 337.28427 | C19: mm | K19: =A68 -> Tongue shear-out, P / (2·a·t) | L19: =IF(ISNUMBER(E68),MIN(E68,5),0) -> 1.3908857
A20: Body width | B20: {=INDEX(Actuators!$J$2:$J$20,MATCH(Inputs!$B$32,Actuators!$A$2:$A$20,0))} -> 83.6 | C20: mm | K20: =A69 -> Tongue net section, P / ((w − d)·t) | L20: =IF(ISNUMBER(E69),MIN(E69,5),0) -> 3.1436495
A21: Rod diameter / female thread | B21: {=INDEX(Actuators!$M$2:$M$20,MATCH(Inputs!$B$32,Actuators!$A$2:$A$20,0))&" mm / "&INDEX(Actuators!$N$2:$N$20,MATCH(Inputs!$B$32,Actuators!$A$2:$A$20,0))} -> 30.13 mm / M12x1.25
A22: Rod female thread depth | B22: {=INDEX(Actuators!$O$2:$O$20,MATCH(Inputs!$B$32,Actuators!$A$2:$A$20,0))} -> 22.2 | C22: mm
A23: Peak force vs holding × margin | B23: =$B$6 -> 6010 | C23: N | D23: =$B$7 -> 3158.1329 | E23: =$B$6/$B$7-1 -> 0.90302316 | F23: =IF(E23>=0,"OK","FAIL") -> OK | G23: Holding check uses peak force as a proxy; spec brake for startup
A24: Layout passes Validation tab | B24: =Validation!D34 -> PASS | D24: PASS | F24: =IF(B24="PASS","OK","FAIL") -> OK | G24: Dimensions are only final once this is OK
A25: Continuous force vs running × margin | B25: {=INDEX(Actuators!$B$2:$B$20,MATCH(Inputs!$B$32,Actuators!$A$2:$A$20,0))*1000} -> 2000 | C25: N | D25: =$B$8 -> 1063.4512 | E25: =B25/D25-1 -> 0.88066934 | F25: =IF(E25>=0,"OK","FAIL") -> OK
A27: 3. Chamber rod end
A28: Item | B28: Value | C28: Unit | D28: Allowable / limit | E28: MS | F28: Status | G28: Note
A29: Selected rod end | B29: =Inputs!$B$43 -> Tolomatic SRE (IMA33)
A30: Bore = front pin diameter | B30: {=INDEX('CAD dims'!$B$106:$B$110,MATCH(Inputs!$B$43,'CAD dims'!$A$106:$A$110,0))} -> 16 | C30: mm
A31: Ball (inner ring) width | B31: {=INDEX('CAD dims'!$C$106:$C$110,MATCH(Inputs!$B$43,'CAD dims'!$A$106:$A$110,0))} -> 21 | C31: mm
A32: Housing width | B32: {=INDEX('CAD dims'!$D$106:$D$110,MATCH(Inputs!$B$43,'CAD dims'!$A$106:$A$110,0))} -> 15 | C32: mm
A33: Head diameter | B33: {=INDEX('CAD dims'!$E$106:$E$110,MATCH(Inputs!$B$43,'CAD dims'!$A$106:$A$110,0))} -> 42 | C33: mm
A34: Static radial rating vs P | B34: {=IF(ISNUMBER(INDEX('CAD dims'!$I$106:$I$110,MATCH(Inputs!$B$43,'CAD dims'!$A$106:$A$110,0))),INDEX('CAD dims'!$I$106:$I$110,MATCH(Inputs!$B$43,'CAD dims'!$A$106:$A$110,0))*1000,"not published")} -> 29000 | C34: N | D34: =$B$10 -> 9015 | E34: =IF(ISNUMBER(B34),B34/D34-1,"") -> 2.2168608 | F34: =IF(ISNUMBER(B34),IF(E34>=0,"OK","FAIL"),"CONFIRM") -> OK | G34: Get the rating from the vendor if blank
A35: Shank thread tension, P / stress area | B35: {=$B$10/INDEX('CAD dims'!$H$106:$H$110,MATCH(Inputs!$B$43,'CAD dims'!$A$106:$A$110,0))} -> 97.882736 | C35: MPa | D35: =Inputs!$B$55 -> 640 | E35: =D35/B35-1 -> 5.5384359 | F35: =IF(E35>=0,"OK","FAIL") -> OK | G35: {="Thread "&INDEX('CAD dims'!$G$106:$G$110,MATCH(Inputs!$B$43,'CAD dims'!$A$106:$A$110,0))} -> Thread M12x1.25
A36: Min thread engagement vs rod thread depth | B36: {=Inputs!$B$56*VALUE(MID(INDEX('CAD dims'!$G$106:$G$110,MATCH(Inputs!$B$43,'CAD dims'!$A$106:$A$110,0)),2,FIND("x",INDEX('CAD dims'!$G$106:$G$110,MATCH(Inputs!$B$43,'CAD dims'!$A$106:$A$110,0)))-2))} -> 12 | C36: mm | D36: =$B$22 -> 22.2 | E36: =D36/B36-1 -> 0.85 | F36: =IF(E36>=0,"OK","FAIL") -> OK | G36: Engage at least this, then lock with a jam nut
A37: Tilt available vs per-axis gimbal angle | B37: {=INDEX('CAD dims'!$F$106:$F$110,MATCH(Inputs!$B$43,'CAD dims'!$A$106:$A$110,0))} -> 10 | C37: deg | D37: =Inputs!$B$13 -> 10 | E37: =B37/D37-1 -> 0 | F37: =IF(E37>=0,"OK","FAIL") -> OK | G37: Conservative: out-of-plane swing ≤ other axis angle
A39: 4. Front pin (shoulder bolt through lugs and rod end)
A40: Item | B40: Value | C40: Unit | D40: Allowable / limit | E40: MS | F40: Status | G40: Note
A41: Gap between lugs = ball width + spacers | B41: =$B$31+2*Inputs!$B$46 -> 21 | C41: mm
A42: Pin grip length = 2 × lug + gap | B42: =2*Inputs!$B$47+$B$41 -> 41 | C42: mm | G42: Shoulder length = grip + washer if used
...

Sheet Actuators
A1: model | B1: cont_kN | C1: peak_kN | D1: vmax_mm_s | E1: stroke_range_mm | F1: retracted_min_mm | G1: extended_at_min_stroke_mm | H1: retracted_max_mm | I1: extended_at_max_stroke_mm | J1: width_mm | K1: height_w_connectors_mm | L1: mass_at_min_stroke_kg | M1: rod_dia_mm | N1: std_rod_female_thread | O1: female_thread_depth_mm | P1: MET_male_thread | Q1: SRE_eye_bore_mm | R1: RCL_clevis_pin_mm | S1: rear_clevis_PCD_pin_bore_mm | T1: price_usd (enter) | U1: stroke_min_mm | V1: stroke_max_mm | W1: dead_length_mm (retracted − stroke) | Y1: cont ≥ running | Z1: peak ≥ holding | AA1: speed ok | AB1: min usable stroke | AC1: max usable stroke | AD1: length / stroke fit | AE1: fits 6 in | AF1: OVERALL | AH1: Required running (kN) | AI1: Required holding (kN)
A2: IMA33-BN05 (1-stack) | B2: 1.62 | C2: 4.45 | D2: 305 | E2: 76.2-457.2 | F2: 292.9 | G2: 369.1 | H2: 673.9 | I2: 1131.1 | J2: 83.6 | K2: 124.6 | L2: 6.1 | M2: 30.13 | N2: M12x1.25 | O2: 22.2 | P2: M16x1.5 | Q2: 16 | R2: 16 | S2: 12 | U2: =VALUE(LEFT(E2,FIND("-",E2)-1)) -> 76.2 | V2: =VALUE(MID(E2,FIND("-",E2)+1,20)) -> 457.2 | W2: =F2-U2 -> 216.7 | Y2: =IF(B2*1000>=Loads!$B$34,"OK","LOW") -> OK | Z2: =IF(C2*1000>=Loads!$B$35,"OK","LOW") -> OK | AA2: =IF(D2>=Geometry!$B$21,"OK","SLOW") -> OK | AB2: =MAX(U2,(Geometry!$B$26+Inputs!$B$34-W2-Inputs!$B$35)/2) -> 77.572289 | AC2: =MIN(V2,Geometry!$B$25-Inputs!$B$34-W2-Inputs!$B$35) -> 83.565934 | AD2: =IF(AB2<=AC2,"OK","NO FIT") -> OK | AE2: =IF(Inputs!$B$5+J2/2<=Inputs!$B$38,"OK","TOO WIDE") -> OK | AF2: =IF(AND(Y2="OK",Z2="OK",AA2="OK",AD2="OK",AE2="OK"),"PASS","FAIL") -> PASS | AH2: =Loads!$B$34/1000 -> 1.0634512 | AI2: =Loads!$B$35/1000 -> 3.1581329
A3: IMA33-RN04 (1-stack) | B3: 2 | C3: 6.01 | D3: 244 | E3: 76.2-457.2 | F3: 292.9 | G3: 369.1 | H3: 673.9 | I3: 1131.1 | J3: 83.6 | K3: 124.6 | L3: 6.1 | M3: 30.13 | N3: M12x1.25 | O3: 22.2 | P3: M16x1.5 | Q3: 16 | R3: 16 | S3: 12 | U3: =VALUE(LEFT(E3,FIND("-",E3)-1)) -> 76.2 | V3: =VALUE(MID(E3,FIND("-",E3)+1,20)) -> 457.2 | W3: =F3-U3 -> 216.7 | Y3: =IF(B3*1000>=Loads!$B$34,"OK","LOW") -> OK | Z3: =IF(C3*1000>=Loads!$B$35,"OK","LOW") -> OK | AA3: =IF(D3>=Geometry!$B$21,"OK","SLOW") -> OK | AB3: =MAX(U3,(Geometry!$B$26+Inputs!$B$34-W3-Inputs!$B$35)/2) -> 77.572289 | AC3: =MIN(V3,Geometry!$B$25-Inputs!$B$34-W3-Inputs!$B$35) -> 83.565934 | AD3: =IF(AB3<=AC3,"OK","NO FIT") -> OK | AE3: =IF(Inputs!$B$5+J3/2<=Inputs!$B$38,"OK","TOO WIDE") -> OK | AF3: =IF(AND(Y3="OK",Z3="OK",AA3="OK",AD3="OK",AE3="OK"),"PASS","FAIL") -> PASS | AH3: =Loads!$B$34/1000 -> 1.0634512 | AI3: =Loads!$B$35/1000 -> 3.1581329
A4: IMA33-RN05 (1-stack) | B4: 1.56 | C4: 4.67 | D4: 305 | E4: 76.2-457.2 | F4: 292.9 | G4: 369.1 | H4: 673.9 | I4: 1131.1 | J4: 83.6 | K4: 124.6 | L4: 6.1 | M4: 30.13 | N4: M12x1.25 | O4: 22.2 | P4: M16x1.5 | Q4: 16 | R4: 16 | S4: 12 | U4: =VALUE(LEFT(E4,FIND("-",E4)-1)) -> 76.2 | V4: =VALUE(MID(E4,FIND("-",E4)+1,20)) -> 457.2 | W4: =F4-U4 -> 216.7 | Y4: =IF(B4*1000>=Loads!$B$34,"OK","LOW") -> OK | Z4: =IF(C4*1000>=Loads!$B$35,"OK","LOW") -> OK | AA4: =IF(D4>=Geometry!$B$21,"OK","SLOW") -> OK | AB4: =MAX(U4,(Geometry!$B$26+Inputs!$B$34-W4-Inputs!$B$35)/2) -> 77.572289 | AC4: =MIN(V4,Geometry!$B$25-Inputs!$B$34-W4-Inputs!$B$35) -> 83.565934 | AD4: =IF(AB4<=AC4,"OK","NO FIT") -> OK | AE4: =IF(Inputs!$B$5+J4/2<=Inputs!$B$38,"OK","TOO WIDE") -> OK | AF4: =IF(AND(Y4="OK",Z4="OK",AA4="OK",AD4="OK",AE4="OK"),"PASS","FAIL") -> PASS | AH4: =Loads!$B$34/1000 -> 1.0634512 | AI4: =Loads!$B$35/1000 -> 3.1581329
A5: IMA33-BN05 (3-stack) | B5: 4 | C5: 4.45 | D5: 292 | E5: 152.4-457.2 | F5: 369.1 | G5: 521.5 | H5: 673.9 | I5: 1131.1 | J5: 83.6 | K5: 124.6 | L5: 8.2 | M5: 30.13 | N5: M12x1.25 | O5: 22.2 | P5: M16x1.5 | Q5: 16 | R5: 16 | S5: 12 | U5: =VALUE(LEFT(E5,FIND("-",E5)-1)) -> 152.4 | V5: =VALUE(MID(E5,FIND("-",E5)+1,20)) -> 457.2 | W5: =F5-U5 -> 216.7 | Y5: =IF(B5*1000>=Loads!$B$34,"OK","LOW") -> OK | Z5: =IF(C5*1000>=Loads!$B$35,"OK","LOW") -> OK | AA5: =IF(D5>=Geometry!$B$21,"OK","SLOW") -> OK | AB5: =MAX(U5,(Geometry!$B$26+Inputs!$B$34-W5-Inputs!$B$35)/2) -> 152.4 | AC5: =MIN(V5,Geometry!$B$25-Inputs!$B$34-W5-Inputs!$B$35) -> 83.565934 | AD5: =IF(AB5<=AC5,"OK","NO FIT") -> NO FIT | AE5: =IF(Inputs!$B$5+J5/2<=Inputs!$B$38,"OK","TOO WIDE") -> OK | AF5: =IF(AND(Y5="OK",Z5="OK",AA5="OK",AD5="OK",AE5="OK"),"PASS","FAIL") -> FAIL | AH5: =Loads!$B$34/1000 -> 1.0634512 | AI5: =Loads!$B$35/1000 -> 3.1581329
A6: IMA33-BN10 (3-stack) | B6: 2 | C6: 4 | D6: 584 | E6: 152.4-457.2 | F6: 369.1 | G6: 521.5 | H6: 673.9 | I6: 1131.1 | J6: 83.6 | K6: 124.6 | L6: 8.2 | M6: 30.13 | N6: M12x1.25 | O6: 22.2 | P6: M16x1.5 | Q6: 16 | R6: 16 | S6: 12 | U6: =VALUE(LEFT(E6,FIND("-",E6)-1)) -> 152.4 | V6: =VALUE(MID(E6,FIND("-",E6)+1,20)) -> 457.2 | W6: =F6-U6 -> 216.7 | Y6: =IF(B6*1000>=Loads!$B$34,"OK","LOW") -> OK | Z6: =IF(C6*1000>=Loads!$B$35,"OK","LOW") -> OK | AA6: =IF(D6>=Geometry!$B$21,"OK","SLOW") -> OK | AB6: =MAX(U6,(Geometry!$B$26+Inputs!$B$34-W6-Inputs!$B$35)/2) -> 152.4 | AC6: =MIN(V6,Geometry!$B$25-Inputs!$B$34-W6-Inputs!$B$35) -> 83.565934 | AD6: =IF(AB6<=AC6,"OK","NO FIT") -> NO FIT | AE6: =IF(Inputs!$B$5+J6/2<=Inputs!$B$38,"OK","TOO WIDE") -> OK | AF6: =IF(AND(Y6="OK",Z6="OK",AA6="OK",AD6="OK",AE6="OK"),"PASS","FAIL") -> FAIL | AH6: =Loads!$B$34/1000 -> 1.0634512 | AI6: =Loads!$B$35/1000 -> 3.1581329
A7: IMA33-RN04 (3-stack) | B7: 4.76 | C7: 11.12 | D7: 234 | E7: 152.4-457.2 | F7: 369.1 | G7: 521.5 | H7: 673.9 | I7: 1131.1 | J7: 83.6 | K7: 124.6 | L7: 8.2 | M7: 30.13 | N7: M12x1.25 | O7: 22.2 | P7: M16x1.5 | Q7: 16 | R7: 16 | S7: 12 | U7: =VALUE(LEFT(E7,FIND("-",E7)-1)) -> 152.4 | V7: =VALUE(MID(E7,FIND("-",E7)+1,20)) -> 457.2 | W7: =F7-U7 -> 216.7 | Y7: =IF(B7*1000>=Loads!$B$34,"OK","LOW") -> OK | Z7: =IF(C7*1000>=Loads!$B$35,"OK","LOW") -> OK | AA7: =IF(D7>=Geometry!$B$21,"OK","SLOW") -> OK | AB7: =MAX(U7,(Geometry!$B$26+Inputs!$B$34-W7-Inputs!$B$35)/2) -> 152.4 | AC7: =MIN(V7,Geometry!$B$25-Inputs!$B$34-W7-Inputs!$B$35) -> 83.565934 | AD7: =IF(AB7<=AC7,"OK","NO FIT") -> NO FIT | AE7: =IF(Inputs!$B$5+J7/2<=Inputs!$B$38,"OK","TOO WIDE") -> OK | AF7: =IF(AND(Y7="OK",Z7="OK",AA7="OK",AD7="OK",AE7="OK"),"PASS","FAIL") -> FAIL | AH7: =Loads!$B$34/1000 -> 1.0634512 | AI7: =Loads!$B$35/1000 -> 3.1581329
A8: IMA33-RN05 (3-stack) | B8: 3.78 | C8: 11.34 | D8: 292 | E8: 152.4-457.2 | F8: 369.1 | G8: 521.5 | H8: 673.9 | I8: 1131.1 | J8: 83.6 | K8: 124.6 | L8: 8.2 | M8: 30.13 | N8: M12x1.25 | O8: 22.2 | P8: M16x1.5 | Q8: 16 | R8: 16 | S8: 12 | U8: =VALUE(LEFT(E8,FIND("-",E8)-1)) -> 152.4 | V8: =VALUE(MID(E8,FIND("-",E8)+1,20)) -> 457.2 | W8: =F8-U8 -> 216.7 | Y8: =IF(B8*1000>=Loads!$B$34,"OK","LOW") -> OK | Z8: =IF(C8*1000>=Loads!$B$35,"OK","LOW") -> OK | AA8: =IF(D8>=Geometry!$B$21,"OK","SLOW") -> OK | AB8: =MAX(U8,(Geometry!$B$26+Inputs!$B$34-W8-Inputs!$B$35)/2) -> 152.4 | AC8: =MIN(V8,Geometry!$B$25-Inputs!$B$34-W8-Inputs!$B$35) -> 83.565934 | AD8: =IF(AB8<=AC8,"OK","NO FIT") -> NO FIT | AE8: =IF(Inputs!$B$5+J8/2<=Inputs!$B$38,"OK","TOO WIDE") -> OK | AF8: =IF(AND(Y8="OK",Z8="OK",AA8="OK",AD8="OK",AE8="OK"),"PASS","FAIL") -> FAIL | AH8: =Loads!$B$34/1000 -> 1.0634512 | AI8: =Loads!$B$35/1000 -> 3.1581329
A9: IMA33-RN10 (3-stack) | B9: 1.89 | C9: 5.69 | D9: 584 | E9: 152.4-457.2 | F9: 369.1 | G9: 521.5 | H9: 673.9 | I9: 1131.1 | J9: 83.6 | K9: 124.6 | L9: 8.2 | M9: 30.13 | N9: M12x1.25 | O9: 22.2 | P9: M16x1.5 | Q9: 16 | R9: 16 | S9: 12 | U9: =VALUE(LEFT(E9,FIND("-",E9)-1)) -> 152.4 | V9: =VALUE(MID(E9,FIND("-",E9)+1,20)) -> 457.2 | W9: =F9-U9 -> 216.7 | Y9: =IF(B9*1000>=Loads!$B$34,"OK","LOW") -> OK | Z9: =IF(C9*1000>=Loads!$B$35,"OK","LOW") -> OK | AA9: =IF(D9>=Geometry!$B$21,"OK","SLOW") -> OK | AB9: =MAX(U9,(Geometry!$B$26+Inputs!$B$34-W9-Inputs!$B$35)/2) -> 152.4 | AC9: =MIN(V9,Geometry!$B$25-Inputs!$B$34-W9-Inputs!$B$35) -> 83.565934 | AD9: =IF(AB9<=AC9,"OK","NO FIT") -> NO FIT | AE9: =IF(Inputs!$B$5+J9/2<=Inputs!$B$38,"OK","TOO WIDE") -> OK | AF9: =IF(AND(Y9="OK",Z9="OK",AA9="OK",AD9="OK",AE9="OK"),"PASS","FAIL") -> FAIL | AH9: =Loads!$B$34/1000 -> 1.0634512 | AI9: =Loads!$B$35/1000 -> 3.1581329
A10: IMA44-BN05 (3-stack) | B10: 7.78 | C10: 10.45 | D10: 267 | E10: 152.4-457.2 | F10: 414.9 | G10: 567.3 | H10: 719.7 | I10: 1176.9 | J10: 110.5 | K10: 151.4 | L10: 16 | M10: 38.08 | N10: M20x1.5 | O10: 25.9 | P10: M20x1.5 | Q10: 20 | R10: 20 | S10: 16 | U10: =VALUE(LEFT(E10,FIND("-",E10)-1)) -> 152.4 | V10: =VALUE(MID(E10,FIND("-",E10)+1,20)) -> 457.2 | W10: =F10-U10 -> 262.5 | Y10: =IF(B10*1000>=Loads!$B$34,"OK","LOW") -> OK | Z10: =IF(C10*1000>=Loads!$B$35,"OK","LOW") -> OK | AA10: =IF(D10>=Geometry!$B$21,"OK","SLOW") -> OK | AB10: =MAX(U10,(Geometry!$B$26+Inputs!$B$34-W10-Inputs!$B$35)/2) -> 152.4 | AC10: =MIN(V10,Geometry!$B$25-Inputs!$B$34-W10-Inputs!$B$35) -> 37.765934 | AD10: =IF(AB10<=AC10,"OK","NO FIT") -> NO FIT | AE10: =IF(Inputs!$B$5+J10/2<=Inputs!$B$38,"OK","TOO WIDE") -> OK | AF10: =IF(AND(Y10="OK",Z10="OK",AA10="OK",AD10="OK",AE10="OK"),"PASS","FAIL") -> FAIL | AH10: =Loads!$B$34/1000 -> 1.0634512 | AI10: =Loads!$B$35/1000 -> 3.1581329
A11: IMA44-BN10 (3-stack) | B11: 3.89 | C11: 11.03 | D11: 533 | E11: 152.4-457.2 | F11: 414.9 | G11: 567.3 | H11: 719.7 | I11: 1176.9 | J11: 110.5 | K11: 151.4 | L11: 16 | M11: 38.08 | N11: M20x1.5 | O11: 25.9 | P11: M20x1.5 | Q11: 20 | R11: 20 | S11: 16 | U11: =VALUE(LEFT(E11,FIND("-",E11)-1)) -> 152.4 | V11: =VALUE(MID(E11,FIND("-",E11)+1,20)) -> 457.2 | W11: =F11-U11 -> 262.5 | Y11: =IF(B11*1000>=Loads!$B$34,"OK","LOW") -> OK | Z11: =IF(C11*1000>=Loads!$B$35,"OK","LOW") -> OK | AA11: =IF(D11>=Geometry!$B$21,"OK","SLOW") -> OK | AB11: =MAX(U11,(Geometry!$B$26+Inputs!$B$34-W11-Inputs!$B$35)/2) -> 152.4 | AC11: =MIN(V11,Geometry!$B$25-Inputs!$B$34-W11-Inputs!$B$35) -> 37.765934 | AD11: =IF(AB11<=AC11,"OK","NO FIT") -> NO FIT | AE11: =IF(Inputs!$B$5+J11/2<=Inputs!$B$38,"OK","TOO WIDE") -> OK | AF11: =IF(AND(Y11="OK",Z11="OK",AA11="OK",AD11="OK",AE11="OK"),"PASS","FAIL") -> FAIL | AH11: =Loads!$B$34/1000 -> 1.0634512 | AI11: =Loads!$B$35/1000 -> 3.1581329
A12: IMA44-BN25 (3-stack) | B12: 1.56 | C12: 4.67 | D12: 1334 | E12: 152.4-457.2 | F12: 414.9 | G12: 567.3 | H12: 719.7 | I12: 1176.9 | J12: 110.5 | K12: 151.4 | L12: 16 | M12: 38.08 | N12: M20x1.5 | O12: 25.9 | P12: M20x1.5 | Q12: 20 | R12: 20 | S12: 16 | U12: =VALUE(LEFT(E12,FIND("-",E12)-1)) -> 152.4 | V12: =VALUE(MID(E12,FIND("-",E12)+1,20)) -> 457.2 | W12: =F12-U12 -> 262.5 | Y12: =IF(B12*1000>=Loads!$B$34,"OK","LOW") -> OK | Z12: =IF(C12*1000>=Loads!$B$35,"OK","LOW") -> OK | AA12: =IF(D12>=Geometry!$B$21,"OK","SLOW") -> OK | AB12: =MAX(U12,(Geometry!$B$26+Inputs!$B$34-W12-Inputs!$B$35)/2) -> 152.4 | AC12: =MIN(V12,Geometry!$B$25-Inputs!$B$34-W12-Inputs!$B$35) -> 37.765934 | AD12: =IF(AB12<=AC12,"OK","NO FIT") -> NO FIT | AE12: =IF(Inputs!$B$5+J12/2<=Inputs!$B$38,"OK","TOO WIDE") -> OK | AF12: =IF(AND(Y12="OK",Z12="OK",AA12="OK",AD12="OK",AE12="OK"),"PASS","FAIL") -> FAIL | AH12: =Loads!$B$34/1000 -> 1.0634512 | AI12: =Loads!$B$35/1000 -> 3.1581329
